<?xml version="1.0" encoding="UTF-8"?>
<testng-results skipped="0" failed="3" total="3" passed="0">
  <reporter-output>
    <line>
      <![CDATA[RunCount=2]]>
    </line>
    <line>
      <![CDATA[RunCount=3]]>
    </line>
    <line>
      <![CDATA[RunCount=2]]>
    </line>
    <line>
      <![CDATA[RunCount=2]]>
    </line>
    <line>
      <![CDATA[RunCount=2]]>
    </line>
    <line>
      <![CDATA[RunCount=2]]>
    </line>
  </reporter-output>
  <suite name="Failed suite [Suite]" duration-ms="11" started-at="2018-08-27T09:44:56Z" finished-at="2018-08-27T09:44:56Z">
    <groups>
    </groups>
    <test name="Api_Select(failed)" duration-ms="2" started-at="2018-08-27T09:44:56Z" finished-at="2018-08-27T09:44:56Z">
      <class name="finup.feather.controller.HttpRequest_TestNG_New">
        <test-method status="FAIL" signature="testMethod(java.lang.String)[pri:0, instance:finup.feather.controller.HttpRequest_TestNG_New@1787f2a0]" name="testMethod" duration-ms="0" started-at="2018-08-27T17:44:56Z" data-provider="file_case_data" finished-at="2018-08-27T17:44:56Z">
          <exception class="java.lang.NullPointerException">
            <full-stacktrace>
              <![CDATA[java.lang.NullPointerException
	at org.testng.internal.Invoker.injectParameters(Invoker.java:1249)
	at org.testng.internal.Invoker.invokeTestMethods(Invoker.java:1125)
	at org.testng.internal.TestMethodWorker.invokeTestMethods(TestMethodWorker.java:125)
	at org.testng.internal.TestMethodWorker.run(TestMethodWorker.java:108)
	at java.util.concurrent.ThreadPoolExecutor.runWorker(ThreadPoolExecutor.java:1142)
	at java.util.concurrent.ThreadPoolExecutor$Worker.run(ThreadPoolExecutor.java:617)
	at java.lang.Thread.run(Thread.java:745)
]]>
            </full-stacktrace>
          </exception> <!-- java.lang.NullPointerException -->
          <reporter-output>
          </reporter-output>
        </test-method> <!-- testMethod -->
      </class> <!-- finup.feather.controller.HttpRequest_TestNG_New -->
    </test> <!-- Api_Select(failed) -->
    <test name="testReport(failed)" duration-ms="5" started-at="2018-08-27T09:44:56Z" finished-at="2018-08-27T09:44:56Z">
      <class name="finup.feather.controller.TestReport">
        <test-method status="PASS" signature="before()[pri:0, instance:finup.feather.controller.TestReport@6ca18a14]" name="before" is-config="true" duration-ms="1" started-at="2018-08-27T17:44:56Z" finished-at="2018-08-27T17:44:56Z">
          <reporter-output>
          </reporter-output>
        </test-method> <!-- before -->
        <test-method status="PASS" signature="before()[pri:0, instance:finup.feather.controller.TestReport@6ca18a14]" name="before" is-config="true" duration-ms="0" started-at="2018-08-27T17:44:56Z" finished-at="2018-08-27T17:44:56Z">
          <reporter-output>
          </reporter-output>
        </test-method> <!-- before -->
        <test-method status="PASS" signature="before()[pri:0, instance:finup.feather.controller.TestReport@6ca18a14]" name="before" is-config="true" duration-ms="0" started-at="2018-08-27T17:44:56Z" finished-at="2018-08-27T17:44:56Z">
          <reporter-output>
          </reporter-output>
        </test-method> <!-- before -->
        <test-method status="FAIL" signature="runnerF1()[pri:0, instance:finup.feather.controller.TestReport@6ca18a14]" name="runnerF1" duration-ms="1" started-at="2018-08-27T17:44:56Z" finished-at="2018-08-27T17:44:56Z">
          <exception class="java.lang.AssertionError">
            <message>
              <![CDATA[FFFF1111message expected [bb] but found [aa]]]>
            </message>
            <full-stacktrace>
              <![CDATA[java.lang.AssertionError: FFFF1111message expected [bb] but found [aa]
	at org.testng.Assert.fail(Assert.java:94)
	at org.testng.Assert.failNotEquals(Assert.java:496)
	at org.testng.Assert.assertEquals(Assert.java:125)
	at org.testng.Assert.assertEquals(Assert.java:178)
	at finup.feather.controller.TestReport.runnerF1(TestReport.java:18)
	at sun.reflect.NativeMethodAccessorImpl.invoke0(Native Method)
	at sun.reflect.NativeMethodAccessorImpl.invoke(NativeMethodAccessorImpl.java:62)
	at sun.reflect.DelegatingMethodAccessorImpl.invoke(DelegatingMethodAccessorImpl.java:43)
	at java.lang.reflect.Method.invoke(Method.java:498)
	at org.testng.internal.MethodInvocationHelper.invokeMethod(MethodInvocationHelper.java:85)
	at org.testng.internal.Invoker.invokeMethod(Invoker.java:659)
	at org.testng.internal.Invoker.retryFailed(Invoker.java:991)
	at org.testng.internal.Invoker.invokeTestMethods(Invoker.java:1171)
	at org.testng.internal.TestMethodWorker.invokeTestMethods(TestMethodWorker.java:125)
	at org.testng.internal.TestMethodWorker.run(TestMethodWorker.java:108)
	at java.util.concurrent.ThreadPoolExecutor.runWorker(ThreadPoolExecutor.java:1142)
	at java.util.concurrent.ThreadPoolExecutor$Worker.run(ThreadPoolExecutor.java:617)
	at java.lang.Thread.run(Thread.java:745)
]]>
            </full-stacktrace>
          </exception> <!-- java.lang.AssertionError -->
          <reporter-output>
          </reporter-output>
        </test-method> <!-- runnerF1 -->
        <test-method status="PASS" signature="before()[pri:0, instance:finup.feather.controller.TestReport@6ca18a14]" name="before" is-config="true" duration-ms="0" started-at="2018-08-27T17:44:56Z" finished-at="2018-08-27T17:44:56Z">
          <reporter-output>
          </reporter-output>
        </test-method> <!-- before -->
        <test-method status="FAIL" signature="runnerF2()[pri:0, instance:finup.feather.controller.TestReport@6ca18a14]" name="runnerF2" duration-ms="0" started-at="2018-08-27T17:44:56Z" finished-at="2018-08-27T17:44:56Z">
          <exception class="java.lang.AssertionError">
            <message>
              <![CDATA[expected [true] but found [false]]]>
            </message>
            <full-stacktrace>
              <![CDATA[java.lang.AssertionError: expected [true] but found [false]
	at org.testng.Assert.fail(Assert.java:94)
	at org.testng.Assert.failNotEquals(Assert.java:496)
	at org.testng.Assert.assertTrue(Assert.java:42)
	at org.testng.Assert.assertTrue(Assert.java:52)
	at finup.feather.controller.TestReport.runnerF2(TestReport.java:23)
	at sun.reflect.NativeMethodAccessorImpl.invoke0(Native Method)
	at sun.reflect.NativeMethodAccessorImpl.invoke(NativeMethodAccessorImpl.java:62)
	at sun.reflect.DelegatingMethodAccessorImpl.invoke(DelegatingMethodAccessorImpl.java:43)
	at java.lang.reflect.Method.invoke(Method.java:498)
	at org.testng.internal.MethodInvocationHelper.invokeMethod(MethodInvocationHelper.java:85)
	at org.testng.internal.Invoker.invokeMethod(Invoker.java:659)
	at org.testng.internal.Invoker.retryFailed(Invoker.java:991)
	at org.testng.internal.Invoker.invokeTestMethods(Invoker.java:1171)
	at org.testng.internal.TestMethodWorker.invokeTestMethods(TestMethodWorker.java:125)
	at org.testng.internal.TestMethodWorker.run(TestMethodWorker.java:108)
	at java.util.concurrent.ThreadPoolExecutor.runWorker(ThreadPoolExecutor.java:1142)
	at java.util.concurrent.ThreadPoolExecutor$Worker.run(ThreadPoolExecutor.java:617)
	at java.lang.Thread.run(Thread.java:745)
]]>
            </full-stacktrace>
          </exception> <!-- java.lang.AssertionError -->
          <reporter-output>
          </reporter-output>
        </test-method> <!-- runnerF2 -->
      </class> <!-- finup.feather.controller.TestReport -->
    </test> <!-- testReport(failed) -->
  </suite> <!-- Failed suite [Suite] -->
</testng-results>
